Workbook

Sheet Capa
A1: Planilha de pontuação paralela — gate tripartite MARIAH v2 (guia × app × revisor)
A3: Camada 1 (este arquivo): esqueleto — respostas de entrada fixadas item a item e RESULTADO ESPERADO em
A4: termos de comportamento (nível I–IV, não avaliável, Prevalência, clamp do 7C). Gerada em 15/08/2026.
A5: Camada 2 (após spec v2.0-draft): preencher colunas 'app' e cruzar célula a célula. Divergência bloqueia.
A7: Conjunto de vetores (despacho da engenharia, 15/08/2026):
A8: V1–V3 Fronteiras recalibradas sem banco: 57/58/59 · 126/127/128 · 207/208/209 (cortes 58/127/208)
A9: V4/V5 Pior caso avaliável (275) / melhor caso (0)
A10: V6 Ativação do Bloco 6.b: fronteiras com banco 64/65 · 141/142 · 230/231 + pior caso avaliável (297)
A11: V7/V8 Eliminatórias: P6.b.2 (anuência) · P2.8 (novo consentimento) → não avaliável
A12: V9 N/A (P6.12/P6.13) não pontua nem altera faixa
A13: V10 Contrato 'descritiva não pontua' (C.1–C.8 no pior valor → escore idêntico)
A14: V11 7C todas presentes → piso do Bloco 7 clampado em 0 (raw −88, sem negativo)
... A37: Camada 2 (20/08/2026): escores esperados validados contra a memória Rev.2 e a spec v2.0-draft (recálculo independente em Python: 31/31 vetores Versão B reproduzidos). V23 atualizado pela F-18a: P6.b.4 = N/A ("sem pedido") → esperado 75/II (antes: 80 com P6.b.4 = Não). Pronta para o cruzamento célula a célula com o app (colunas G–J).

Sheet Vetores
A1: Vetor | B1: Versão | C1: Banco? | D1: Hipótese / cenário | E1: Escore esperado (memória Rev.2) | F1: Resultado esperado (comportamento) | G1: Escore app | H1: Nível/resultado app | I1: Δ | J1: Status cruzamento
A2: V1a | B2: B | C2: não | D2: Fronteira I/II — 1 abaixo do corte (57) | E2: 57 | F2: I | J2: AGUARDA APP — camada 2 validada (memória Rev.2 + F-18a)
A3: V1b | B3: B | C3: não | D3: Fronteira I/II — no corte (58) | E3: 58 | F3: I | J3: AGUARDA APP — camada 2 validada (memória Rev.2 + F-18a)
A4: V1c | B4: B | C4: não | D4: Fronteira I/II — 1 acima (59) | E4: 59 | F4: II | J4: AGUARDA APP — camada 2 validada (memória Rev.2 + F-18a)
A5: V2a | B5: B | C5: não | D5: Fronteira II/III — 1 abaixo (126) | E5: 126 | F5: II | J5: AGUARDA APP — camada 2 validada (memória Rev.2 + F-18a)
A6: V2b | B6: B | C6: não | D6: Fronteira II/III — no corte (127) | E6: 127 | F6: II | J6: AGUARDA APP — camada 2 validada (memória Rev.2 + F-18a)
A7: V2c | B7: B | C7: não | D7: Fronteira II/III — 1 acima (128) | E7: 128 | F7: III | J7: AGUARDA APP — camada 2 validada (memória Rev.2 + F-18a)
A8: V3a | B8: B | C8: não | D8: Fronteira III/IV — 1 abaixo (207) | E8: 207 | F8: III | J8: AGUARDA APP — camada 2 validada (memória Rev.2 + F-18a)
A9: V3b | B9: B | C9: não | D9: Fronteira III/IV — no corte (208) | E9: 208 | F9: III | J9: AGUARDA APP — camada 2 validada (memória Rev.2 + F-18a)
A10: V3c | B10: B | C10: não | D10: Fronteira III/IV — 1 acima (209) | E10: 209 | F10: IV | J10: AGUARDA APP — camada 2 validada (memória Rev.2 + F-18a)
A11: V4 | B11: B | C11: não | D11: Pior caso sem banco (teto 275; Bloco 7 = +75). P4.1/P4.2 incluídos: o que se verifica é o ESCORE — IV por faixa e por Prevalência | E11: 275 | F11: IV | J11: AGUARDA APP — camada 2 validada (memória Rev.2 + F-18a)
A12: V5 | B12: B | C12: não | D12: Melhor caso (tudo seguro, mitigações presentes, 7C ausente) | E12: 0 | F12: I | J12: AGUARDA APP — camada 2 validada (memória Rev.2 + F-18a)
A13: V6a | B13: B | C13: sim | D13: Com banco — fronteira I/II abaixo (64) | E13: 64 | F13: I | J13: AGUARDA APP — camada 2 validada (memória Rev.2 + F-18a)
... A19: V6g | B19: B | C19: sim | D19: Com banco — pior caso AVALIÁVEL (275+22; o 304 teórico inclui a eliminatória → V14). P4.1/P4.2 incluídos: verifica-se o ESCORE | E19: 297 | F19: IV | J19: AGUARDA APP — camada 2 validada (memória Rev.2 + F-18a)
A20: V7 | B20: B | C20: sim | D20: Eliminatória P6.b.2 (sem Termo de Anuência) — mesmo com escore baixo | E20: — | F20: não avaliável | J20: AGUARDA APP — camada 2 validada (memória Rev.2 + F-18a)
A21: V8 | B21: B | C21: não | D21: Eliminatória P2.8 (adaptativo sem plano de novo consentimento) | E21: — | F21: não avaliável | J21: AGUARDA APP — camada 2 validada (memória Rev.2 + F-18a)
A22: V9 | B22: B | C22: não | D22: N/A em P6.12/P6.13 — não pontua e não altera faixa (idêntico a V1b) | E22: 58 | F22: I | J22: AGUARDA APP — camada 2 validada (memória Rev.2 + F-18a)
A23: V10 | B23: B | C23: não | D23: Contrato descritiva: C.1–C.8 no pior valor → escore idêntico a V5 (trava anti-vazamento) | E23: 0 | F23: I | J23: AGUARDA APP — camada 2 validada (memória Rev.2 + F-18a)
A24: V11 | B24: B | C24: não | D24: 7C todas presentes + 7B todas presentes: raw −88 → piso clampado em 0, sem negativo | E24: 0 | F24: I | J24: AGUARDA APP — camada 2 validada (memória Rev.2 + F-18a)
A25: V12 | B25: B | C25: não | D25: 7C todas ausentes no pior caso: NÃO infla o teto (275, não 298) — trava do cenário A. Verifica-se o ESCORE | E25: 275 | F25: IV | J25: AGUARDA APP — camada 2 validada (memória Rev.2 + F-18a)
A26: V13 | B26: B | C26: não | D26: P4.1 = Sim com escore 3 (faixa I): Cláusula de Prevalência força Nível IV | E26: 3 | F26: IV (Prevalência) | J26: AGUARDA APP — camada 2 validada (memória Rev.2 + F-18a)
A27: V14 | B27: B | C27: sim | D27: Eliminatória + escore alto (304 com P6.b.2 violada): vence não avaliável, nunca IV | E27: — | F27: não avaliável | J27: AGUARDA APP — camada 2 validada (memória Rev.2 + F-18a)
A28: V15 | B28: B | C28: sim | D28: Checklist TCLE parcial (8 de 9 critérios): devolução, NÃO pontua | E28: — | F28: não avaliável (devolução) | J28: AGUARDA APP — camada 2 validada (memória Rev.2 + F-18a)
A29: V20 | B29: B | C29: sim | D29: Diligência P6.b.4.1 = 'Não' (acesso a identificáveis NÃO indispensável): devolução, não pontua | E29: — | F29: não avaliável (devolução) | J29: AGUARDA APP — camada 2 validada (memória Rev.2 + F-18a)
A30: V21 | B30: B | C30: sim | D30: Diligência P6.b.7 = 'Não' (sem declaração do Controlador): devolução, não pontua | E30: — | F30: não avaliável (devolução) | J30: AGUARDA APP — camada 2 validada (memória Rev.2 + F-18a)
A31: V22 | B31: B | C31: sim | D31: Diligência violada + escore alto (297, teto avaliável): vence não avaliável, nunca IV (espelho do V14 para diligências) | E31: — | F31: não avaliável (devolução) | J31: AGUARDA APP — camada 2 validada (memória Rev.2 + F-18a)
A32: V23 | B32: B | C32: sim | D32: Sem pedido de dispensa: P6.b.4 = N/A (F-18a) → 0 pts; P6.b.4.1 e P6.b.6 OCULTAS (não exibidas, não respondidas); P6.b.7 aplica-se (banco) = Sim. Escore 75 → II | E32: 75 | F32: II | J32: AGUARDA APP — camada 2 validada (memória Rev.2 + F-18a)
A33: V16 | B33: B | C33: — | D33: Arredondamento .5: meia-unidade para cima sobre frações do baseline (50/238, 110/238, 180/238). Ex.: 110/238 × 304 = 140,5 → 141. | E33: 64 / 141 / 230 | F33: cortes com banco reproduzidos | J33: AGUARDA APP — camada 2 validada (memória Rev.2 + F-18a)
A34: V17 | B34: A | C34: — | D34: Fronteiras de contagem por eixo (0/1/2/3/4/5) com Eixo 2 = 12 e Eixo 3 = 13 perguntas; regra especial do 3.b; cortes absolutos mantidos (D-1 confirmado). | E34: — | F34: ver aba V17_VersaoA | J34: AGUARDA APP — camada 2 validada (memória Rev.2 + F-18a)
A35: V18 | B35: A/B | C35: — | D35: Mapa de IDs antigos→novos: export v1 relido sob CHANGELOG v2. | E35: — | F35: ver aba V18_MapaIDs | J35: PENDENTE (aguarda CHANGELOG v2)
A36: V19 | B36: A→B | C36: — | D36: Vetor auxiliar (CONFIRMADO pela engenharia, 15/08): modo Triagem A→B com protocolo III em A → relatório combinado coerente pós-mudança (plano §9.6.6). | E36: — | F36: relatório combinado coerente | J36: AGUARDA APP — camada 2 validada (memória Rev.2 + F-18a)

Sheet Itens_B
A1: id | B1: bloco | C1: pontos | D1: efeito | E1: resposta_de_risco | F1: eliminatório | G1: nota
A2: P1.1 | B2: 1 | C2: 3 | D2: risco | E2: Não
A3: P1.2 | B3: 1 | C3: 3 | D3: risco | E3: Não
A4: P1.3 | B4: 1 | C4: 3 | D4: risco | E4: Não
A5: P1.4 | B5: 1 | C5: 3 | D5: risco | E5: Não
A6: P1.5 | B6: 1 | C6: 3 | D6: risco | E6: Não
A7: P1.6 | B7: 1 | C7: 3 | D7: risco | E7: Não
A8: P1.7 | B8: 1 | C8: 4 | D8: risco | E8: Não
A9: P2.1 | B9: 2 | C9: 3 | D9: risco | E9: Sim
A10: P2.2 | B10: 2 | C10: 3 | D10: risco | E10: Sim
A11: P2.3 | B11: 2 | C11: 3 | D11: risco | E11: Sim
A12: P2.4 | B12: 2 | C12: 2 | D12: risco | E12: Não
A13: P2.5 | B13: 2 | C13: 2 | D13: risco | E13: Não
... A15: P2.7 | B15: 2 | C15: 2 | D15: risco | E15: Não
A16: P2.8 | B16: 2 | C16: 0 | D16: risco | E16: Não | F16: SIM | G16: [ELIMINATÓRIO] plano de novo consentimento (só se P2.2 = Sim)
A17: P3.1 | B17: 3 | C17: 2 | D17: risco | E17: Sim
A18: P3.2 | B18: 3 | C18: 2 | D18: risco | E18: Sim
A19: P3.3 | B19: 3 | C19: 2 | D19: risco | E19: Não
A20: P3.4 | B20: 3 | C20: 2 | D20: risco | E20: Não
A21: P3.5 | B21: 3 | C21: 2 | D21: risco | E21: Não
A22: P3.6 | B22: 3 | C22: 2 | D22: risco | E22: Não
A23: P3.7 | B23: 3 | C23: 2 | D23: risco | E23: Não
A24: P4.1 | B24: 4 | C24: 3 | D24: risco | E24: Sim | G24: Prevalência Ética
A25: P4.2 | B25: 4 | C25: 3 | D25: risco | E25: Sim | G25: Prevalência Ética
A26: P4.3 | B26: 4 | C26: 2 | D26: risco | E26: Não
A27: P5.1 | B27: 5 | C27: 6 | D27: risco | E27: Sim
A28: P5.2 | B28: 5 | C28: 6 | D28: risco | E28: Sim
A29: P5.3 | B29: 5 | C29: 6 | D29: risco | E29: Sim
A30: P5.4 | B30: 5 | C30: 6 | D30: risco | E30: Sim
A31: P5.5 | B31: 5 | C31: 6 | D31: risco | E31: Sim
A32: P5.6 | B32: 5 | C32: 5 | D32: risco | E32: Não
A33: P5.7 | B33: 5 | C33: 5 | D33: risco | E33: Não
A34: P5.8 | B34: 5 | C34: 6 | D34: risco | E34: Não
A35: P5.9 | B35: 5 | C35: 6 | D35: risco | E35: Não
A36: P5.10 | B36: 5 | C36: 5 | D36: risco | E36: Sim
A37: P5.11 | B37: 5 | C37: 5 | D37: risco | E37: Sim
... A48: P6.11 | B48: 6 | C48: 5 | D48: risco | E48: Não
A49: P6.12 | B49: 6 | C49: 5 | D49: risco | E49: Sim | G49: admite N/A
A50: P6.13 | B50: 6 | C50: 7 | D50: risco | E50: Não | G50: admite N/A (só PLN/LLM/sintéticos)
A51: P6.b.1 | B51: 6.b | C51: 7 | D51: risco | E51: Não
...

Sheet Entradas_B
A1: id | B1: bloco | C1: V1a | D1: V1b | E1: V1c | F1: V2a | G1: V2b | H1: V2c | I1: V3a | J1: V3b | K1: V3c | L1: V4 | M1: V5 | N1: V6a | O1: V6b | P1: V6c | Q1: V6d | R1: V6e | S1: V6f | T1: V6g | U1: V7 | V1: V8 | W1: V9 | X1: V10 | Y1: V11 | Z1: V12 | AA1: V13 | AB1: V14 | AC1: V15 | AD1: V20 | AE1: V21 | AF1: V22 | AG1: V23
A2: P1.1 | B2: 1 | C2: Não | D2: Não | E2: Não | F2: Não | G2: Não | H2: Não | I2: Não | J2: Não | K2: Não | L2: Não | M2: Sim | N2: Não | O2: Não | P2: Não | Q2: Não | R2: Não | S2: Não | T2: Não | U2: Sim | V2: Sim | W2: Não | X2: Sim | Y2: Sim | Z2: Não | AA2: Sim | AB2: Não | AC2: Sim | AD2: Sim | AE2: Sim | AF2: Não | AG2: Não
A3: P1.2 | B3: 1 | C3: Não | D3: Não | E3: Não | F3: Não | G3: Não | H3: Não | I3: Não | J3: Não | K3: Não | L3: Não | M3: Sim | N3: Não | O3: Não | P3: Não | Q3: Não | R3: Não | S3: Não | T3: Não | U3: Sim | V3: Sim | W3: Não | X3: Sim | Y3: Sim | Z3: Não | AA3: Sim | AB3: Não | AC3: Sim | AD3: Sim | AE3: Sim | AF3: Não | AG3: Não
A4: P1.3 | B4: 1 | C4: Não | D4: Não | E4: Não | F4: Não | G4: Não | H4: Não | I4: Não | J4: Não | K4: Não | L4: Não | M4: Sim | N4: Não | O4: Não | P4: Não | Q4: Não | R4: Não | S4: Não | T4: Não | U4: Sim | V4: Sim | W4: Não | X4: Sim | Y4: Sim | Z4: Não | AA4: Sim | AB4: Não | AC4: Sim | AD4: Sim | AE4: Sim | AF4: Não | AG4: Não
A5: P1.4 | B5: 1 | C5: Não | D5: Não | E5: Não | F5: Não | G5: Não | H5: Não | I5: Não | J5: Não | K5: Não | L5: Não | M5: Sim | N5: Não | O5: Não | P5: Não | Q5: Não | R5: Não | S5: Não | T5: Não | U5: Sim | V5: Sim | W5: Não | X5: Sim | Y5: Sim | Z5: Não | AA5: Sim | AB5: Não | AC5: Sim | AD5: Sim | AE5: Sim | AF5: Não | AG5: Não
A6: P1.5 | B6: 1 | C6: Não | D6: Não | E6: Não | F6: Não | G6: Não | H6: Não | I6: Não | J6: Não | K6: Não | L6: Não | M6: Sim | N6: Não | O6: Não | P6: Não | Q6: Não | R6: Não | S6: Não | T6: Não | U6: Sim | V6: Sim | W6: Não | X6: Sim | Y6: Sim | Z6: Não | AA6: Sim | AB6: Não | AC6: Sim | AD6: Sim | AE6: Sim | AF6: Não | AG6: Não
A7: P1.6 | B7: 1 | C7: Não | D7: Não | E7: Não | F7: Não | G7: Não | H7: Não | I7: Não | J7: Não | K7: Não | L7: Não | M7: Sim | N7: Não | O7: Não | P7: Não | Q7: Não | R7: Não | S7: Não | T7: Não | U7: Sim | V7: Sim | W7: Não | X7: Sim | Y7: Sim | Z7: Não | AA7: Sim | AB7: Não | AC7: Sim | AD7: Sim | AE7: Sim | AF7: Não | AG7: Não
A8: P1.7 | B8: 1 | C8: Não | D8: Não | E8: Não | F8: Não | G8: Não | H8: Não | I8: Não | J8: Não | K8: Não | L8: Não | M8: Sim | N8: Não | O8: Não | P8: Não | Q8: Não | R8: Não | S8: Não | T8: Não | U8: Sim | V8: Sim | W8: Não | X8: Sim | Y8: Sim | Z8: Não | AA8: Sim | AB8: Não | AC8: Sim | AD8: Sim | AE8: Sim | AF8: Não | AG8: Não
A9: P2.1 | B9: 2 | C9: Sim | D9: Sim | E9: Sim | F9: Sim | G9: Sim | H9: Sim | I9: Sim | J9: Sim | K9: Sim | L9: Sim | M9: Não | N9: Sim | O9: Sim | P9: Sim | Q9: Sim | R9: Sim | S9: Sim | T9: Sim | U9: Não | V9: Não | W9: Sim | X9: Não | Y9: Não | Z9: Sim | AA9: Não | AB9: Sim | AC9: Não | AD9: Não | AE9: Não | AF9: Sim | AG9: Sim
A10: P2.2 | B10: 2 | C10: Sim | D10: Sim | E10: Sim | F10: Sim | G10: Sim | H10: Sim | I10: Sim | J10: Sim | K10: Sim | L10: Sim | M10: Não | N10: Sim | O10: Sim | P10: Sim | Q10: Sim | R10: Sim | S10: Sim | T10: Sim | U10: Não | V10: Sim | W10: Sim | X10: Não | Y10: Não | Z10: Sim | AA10: Não | AB10: Sim | AC10: Não | AD10: Não | AE10: Não | AF10: Sim | AG10: Sim
A11: P2.3 | B11: 2 | C11: Sim | D11: Não | E11: Sim | F11: Sim | G11: Sim | H11: Não | I11: Sim | J11: Sim | K11: Sim | L11: Sim | M11: Não | N11: Não | O11: Sim | P11: Sim | Q11: Sim | R11: Sim | S11: Sim | T11: Sim | U11: Não | V11: Não | W11: Não | X11: Não | Y11: Não | Z11: Sim | AA11: Não | AB11: Sim | AC11: Não | AD11: Não | AE11: Não | AF11: Sim | AG11: Não
A12: P2.4 | B12: 2 | C12: Não | D12: Não | E12: Não | F12: Não | G12: Não | H12: Não | I12: Não | J12: Não | K12: Não | L12: Não | M12: Sim | N12: Não | O12: Não | P12: Não | Q12: Não | R12: Não | S12: Não | T12: Não | U12: Sim | V12: Sim | W12: Não | X12: Sim | Y12: Sim | Z12: Não | AA12: Sim | AB12: Não | AC12: Sim | AD12: Sim | AE12: Sim | AF12: Não | AG12: Não
... A80: C.8 | B80: — | C80: (neutro) | D80: (neutro) | E80: (neutro) | F80: (neutro) | G80: (neutro) | H80: (neutro) | I80: (neutro) | J80: (neutro) | K80: (neutro) | L80: (neutro) | M80: (neutro) | N80: (neutro) | O80: (neutro) | P80: (neutro) | Q80: (neutro) | R80: (neutro) | S80: (neutro) | T80: (neutro) | U80: (neutro) | V80: (neutro) | W80: (neutro) | X80: sim, outra forma (descrever) | Y80: (neutro) | Z80: (neutro) | AA80: (neutro) | AB80: (neutro) | AC80: (neutro) | AD80: (neutro) | AE80: (neutro) | AF80: (neutro) | AG80: (neutro)

Sheet Calculo_B
A1: item/bloco | B1: V1a | C1: V1b | D1: V1c | E1: V2a | F1: V2b | G1: V2c | H1: V3a | I1: V3b | J1: V3c | K1: V4 | L1: V5 | M1: V6a | N1: V6b | O1: V6c | P1: V6d | Q1: V6e | R1: V6f | S1: V6g | T1: V7 | U1: V8 | V1: V9 | W1: V10 | X1: V11 | Y1: V12 | Z1: V13 | AA1: V14 | AB1: V15 | AC1: V20 | AD1: V21 | AE1: V22 | AF1: V23
A2: banco ativado? | B2: não | C2: não | D2: não | E2: não | F2: não | G2: não | H2: não | I2: não | J2: não | K2: não | L2: não | M2: sim | N2: sim | O2: sim | P2: sim | Q2: sim | R2: sim | S2: sim | T2: sim | U2: não | V2: não | W2: não | X2: não | Y2: não | Z2: não | AA2: sim | AB2: sim | AC2: sim | AD2: sim | AE2: sim | AF2: sim
A3: contribuições →
A4: P1.1 | B4: =IF(Entradas_B!C2="N/A",0,IF(Itens_B!$D2="risco",IF(Entradas_B!C2=Itens_B!$E2,Itens_B!$C2,0),IF(Itens_B!$D2="mitigacao",IF(Entradas_B!C2="Sim",-Itens_B!$C2,Itens_B!$C2),IF(Itens_B!$D2="evidencia",IF(Entradas_B!C2="Sim",-Itens_B!$C2,0),0)))) | C4: =IF(Entradas_B!D2="N/A",0,IF(Itens_B!$D2="risco",IF(Entradas_B!D2=Itens_B!$E2,Itens_B!$C2,0),IF(Itens_B!$D2="mitigacao",IF(Entradas_B!D2="Sim",-Itens_B!$C2,Itens_B!$C2),IF(Itens_B!$D2="evidencia",IF(Entradas_B!D2="Sim",-Itens_B!$C2,0),0)))) | D4: =IF(Entradas_B!E2="N/A",0,IF(Itens_B!$D2="risco",IF(Entradas_B!E2=Itens_B!$E2,Itens_B!$C2,0),IF(Itens_B!$D2="mitigacao",IF(Entradas_B!E2="Sim",-Itens_B!$C2,Itens_B!$C2),IF(Itens_B!$D2="evidencia",IF(Entradas_B!E2="Sim",-Itens_B!$C2,0),0)))) | E4: =IF(Entradas_B!F2="N/A",0,IF(Itens_B!$D2="risco",IF(Entradas_B!F2=Itens_B!$E2,Itens_B!$C2,0),IF(Itens_B!$D2="mitigacao",IF(Entradas_B!F2="Sim",-Itens_B!$C2,Itens_B!$C2),IF(Itens_B!$D2="evidencia",IF(Entradas_B!F2="Sim",-Itens_B!$C2,0),0)))) | F4: =IF(Entradas_B!G2="N/A",0,IF(Itens_B!$D2="risco",IF(Entradas_B!G2=Itens_B!$E2,Itens_B!$C2,0),IF(Itens_B!$D2="mitigacao",IF(Entradas_B!G2="Sim",-Itens_B!$C2,Itens_B!$C2),IF(Itens_B!$D2="evidencia",IF(Entradas_B!G2="Sim",-Itens_B!$C2,0),0)))) | G4: =IF(Entradas_B!H2="N/A",0,IF(Itens_B!$D2="risco",IF(Entradas_B!H2=Itens_B!$E2,Itens_B!$C2,0),IF(Itens_B!$D2="mitigacao",IF(Entradas_B!H2="Sim",-Itens_B!$C2,Itens_B!$C2),IF(Itens_B!$D2="evidencia",IF(Entradas_B!H2="Sim",-Itens_B!$C2,0),0)))) | H4: =IF(Entradas_B!I2="N/A",0,IF(Itens_B!$D2="risco",IF(Entradas_B!I2=Itens_B!$E2,Itens_B!$C2,0),IF(Itens_B!$D2="mitigacao",IF(Entradas_B!I2="Sim",-Itens_B!$C2,Itens_B!$C2),IF(Itens_B!$D2="evidencia",IF(Entradas_B!I2="Sim",-Itens_B!$C2,0),0)))) | I4: =IF(Entradas_B!J2="N/A",0,IF(Itens_B!$D2="risco",IF(Entradas_B!J2=Itens_B!$E2,Itens_B!$C2,0),IF(Itens_B!$D2="mitigacao",IF(Entradas_B!J2="Sim",-Itens_B!$C2,Itens_B!$C2),IF(Itens_B!$D2="evidencia",IF(Entradas_B!J2="Sim",-Itens_B!$C2,0),0)))) | ... AF4: =IF(Entradas_B!AG2="N/A",0,IF(Itens_B!$D2="risco",IF(Entradas_B!AG2=Itens_B!$E2,Itens_B!$C2,0),IF(Itens_B!$D2="mitigacao",IF(Entradas_B!AG2="Sim",-Itens_B!$C2,Itens_B!$C2),IF(Itens_B!$D2="evidencia",IF(Entradas_B!AG2="Sim",-Itens_B!$C2,0),0))))
A5: P1.2 | B5: =IF(Entradas_B!C3="N/A",0,IF(Itens_B!$D3="risco",IF(Entradas_B!C3=Itens_B!$E3,Itens_B!$C3,0),IF(Itens_B!$D3="mitigacao",IF(Entradas_B!C3="Sim",-Itens_B!$C3,Itens_B!$C3),IF(Itens_B!$D3="evidencia",IF(Entradas_B!C3="Sim",-Itens_B!$C3,0),0)))) | C5: =IF(Entradas_B!D3="N/A",0,IF(Itens_B!$D3="risco",IF(Entradas_B!D3=Itens_B!$E3,Itens_B!$C3,0),IF(Itens_B!$D3="mitigacao",IF(Entradas_B!D3="Sim",-Itens_B!$C3,Itens_B!$C3),IF(Itens_B!$D3="evidencia",IF(Entradas_B!D3="Sim",-Itens_B!$C3,0),0)))) | D5: =IF(Entradas_B!E3="N/A",0,IF(Itens_B!$D3="risco",IF(Entradas_B!E3=Itens_B!$E3,Itens_B!$C3,0),IF(Itens_B!$D3="mitigacao",IF(Entradas_B!E3="Sim",-Itens_B!$C3,Itens_B!$C3),IF(Itens_B!$D3="evidencia",IF(Entradas_B!E3="Sim",-Itens_B!$C3,0),0)))) | E5: =IF(Entradas_B!F3="N/A",0,IF(Itens_B!$D3="risco",IF(Entradas_B!F3=Itens_B!$E3,Itens_B!$C3,0),IF(Itens_B!$D3="mitigacao",IF(Entradas_B!F3="Sim",-Itens_B!$C3,Itens_B!$C3),IF(Itens_B!$D3="evidencia",IF(Entradas_B!F3="Sim",-Itens_B!$C3,0),0)))) | F5: =IF(Entradas_B!G3="N/A",0,IF(Itens_B!$D3="risco",IF(Entradas_B!G3=Itens_B!$E3,Itens_B!$C3,0),IF(Itens_B!$D3="mitigacao",IF(Entradas_B!G3="Sim",-Itens_B!$C3,Itens_B!$C3),IF(Itens_B!$D3="evidencia",IF(Entradas_B!G3="Sim",-Itens_B!$C3,0),0)))) | G5: =IF(Entradas_B!H3="N/A",0,IF(Itens_B!$D3="risco",IF(Entradas_B!H3=Itens_B!$E3,Itens_B!$C3,0),IF(Itens_B!$D3="mitigacao",IF(Entradas_B!H3="Sim",-Itens_B!$C3,Itens_B!$C3),IF(Itens_B!$D3="evidencia",IF(Entradas_B!H3="Sim",-Itens_B!$C3,0),0)))) | H5: =IF(Entradas_B!I3="N/A",0,IF(Itens_B!$D3="risco",IF(Entradas_B!I3=Itens_B!$E3,Itens_B!$C3,0),IF(Itens_B!$D3="mitigacao",IF(Entradas_B!I3="Sim",-Itens_B!$C3,Itens_B!$C3),IF(Itens_B!$D3="evidencia",IF(Entradas_B!I3="Sim",-Itens_B!$C3,0),0)))) | I5: =IF(Entradas_B!J3="N/A",0,IF(Itens_B!$D3="risco",IF(Entradas_B!J3=Itens_B!$E3,Itens_B!$C3,0),IF(Itens_B!$D3="mitigacao",IF(Entradas_B!J3="Sim",-Itens_B!$C3,Itens_B!$C3),IF(Itens_B!$D3="evidencia",IF(Entradas_B!J3="Sim",-Itens_B!$C3,0),0)))) | ... AF5: =IF(Entradas_B!AG3="N/A",0,IF(Itens_B!$D3="risco",IF(Entradas_B!AG3=Itens_B!$E3,Itens_B!$C3,0),IF(Itens_B!$D3="mitigacao",IF(Entradas_B!AG3="Sim",-Itens_B!$C3,Itens_B!$C3),IF(Itens_B!$D3="evidencia",IF(Entradas_B!AG3="Sim",-Itens_B!$C3,0),0))))
A6: P1.3 | B6: =IF(Entradas_B!C4="N/A",0,IF(Itens_B!$D4="risco",IF(Entradas_B!C4=Itens_B!$E4,Itens_B!$C4,0),IF(Itens_B!$D4="mitigacao",IF(Entradas_B!C4="Sim",-Itens_B!$C4,Itens_B!$C4),IF(Itens_B!$D4="evidencia",IF(Entradas_B!C4="Sim",-Itens_B!$C4,0),0)))) | C6: =IF(Entradas_B!D4="N/A",0,IF(Itens_B!$D4="risco",IF(Entradas_B!D4=Itens_B!$E4,Itens_B!$C4,0),IF(Itens_B!$D4="mitigacao",IF(Entradas_B!D4="Sim",-Itens_B!$C4,Itens_B!$C4),IF(Itens_B!$D4="evidencia",IF(Entradas_B!D4="Sim",-Itens_B!$C4,0),0)))) | D6: =IF(Entradas_B!E4="N/A",0,IF(Itens_B!$D4="risco",IF(Entradas_B!E4=Itens_B!$E4,Itens_B!$C4,0),IF(Itens_B!$D4="mitigacao",IF(Entradas_B!E4="Sim",-Itens_B!$C4,Itens_B!$C4),IF(Itens_B!$D4="evidencia",IF(Entradas_B!E4="Sim",-Itens_B!$C4,0),0)))) | E6: =IF(Entradas_B!F4="N/A",0,IF(Itens_B!$D4="risco",IF(Entradas_B!F4=Itens_B!$E4,Itens_B!$C4,0),IF(Itens_B!$D4="mitigacao",IF(Entradas_B!F4="Sim",-Itens_B!$C4,Itens_B!$C4),IF(Itens_B!$D4="evidencia",IF(Entradas_B!F4="Sim",-Itens_B!$C4,0),0)))) | F6: =IF(Entradas_B!G4="N/A",0,IF(Itens_B!$D4="risco",IF(Entradas_B!G4=Itens_B!$E4,Itens_B!$C4,0),IF(Itens_B!$D4="mitigacao",IF(Entradas_B!G4="Sim",-Itens_B!$C4,Itens_B!$C4),IF(Itens_B!$D4="evidencia",IF(Entradas_B!G4="Sim",-Itens_B!$C4,0),0)))) | G6: =IF(Entradas_B!H4="N/A",0,IF(Itens_B!$D4="risco",IF(Entradas_B!H4=Itens_B!$E4,Itens_B!$C4,0),IF(Itens_B!$D4="mitigacao",IF(Entradas_B!H4="Sim",-Itens_B!$C4,Itens_B!$C4),IF(Itens_B!$D4="evidencia",IF(Entradas_B!H4="Sim",-Itens_B!$C4,0),0)))) | H6: =IF(Entradas_B!I4="N/A",0,IF(Itens_B!$D4="risco",IF(Entradas_B!I4=Itens_B!$E4,Itens_B!$C4,0),IF(Itens_B!$D4="mitigacao",IF(Entradas_B!I4="Sim",-Itens_B!$C4,Itens_B!$C4),IF(Itens_B!$D4="evidencia",IF(Entradas_B!I4="Sim",-Itens_B!$C4,0),0)))) | I6: =IF(Entradas_B!J4="N/A",0,IF(Itens_B!$D4="risco",IF(Entradas_B!J4=Itens_B!$E4,Itens_B!$C4,0),IF(Itens_B!$D4="mitigacao",IF(Entradas_B!J4="Sim",-Itens_B!$C4,Itens_B!$C4),IF(Itens_B!$D4="evidencia",IF(Entradas_B!J4="Sim",-Itens_B!$C4,0),0)))) | ... AF6: =IF(Entradas_B!AG4="N/A",0,IF(Itens_B!$D4="risco",IF(Entradas_B!AG4=Itens_B!$E4,Itens_B!$C4,0),IF(Itens_B!$D4="mitigacao",IF(Entradas_B!AG4="Sim",-Itens_B!$C4,Itens_B!$C4),IF(Itens_B!$D4="evidencia",IF(Entradas_B!AG4="Sim",-Itens_B!$C4,0),0))))
A7: P1.4 | B7: =IF(Entradas_B!C5="N/A",0,IF(Itens_B!$D5="risco",IF(Entradas_B!C5=Itens_B!$E5,Itens_B!$C5,0),IF(Itens_B!$D5="mitigacao",IF(Entradas_B!C5="Sim",-Itens_B!$C5,Itens_B!$C5),IF(Itens_B!$D5="evidencia",IF(Entradas_B!C5="Sim",-Itens_B!$C5,0),0)))) | C7: =IF(Entradas_B!D5="N/A",0,IF(Itens_B!$D5="risco",IF(Entradas_B!D5=Itens_B!$E5,Itens_B!$C5,0),IF(Itens_B!$D5="mitigacao",IF(Entradas_B!D5="Sim",-Itens_B!$C5,Itens_B!$C5),IF(Itens_B!$D5="evidencia",IF(Entradas_B!D5="Sim",-Itens_B!$C5,0),0)))) | D7: =IF(Entradas_B!E5="N/A",0,IF(Itens_B!$D5="risco",IF(Entradas_B!E5=Itens_B!$E5,Itens_B!$C5,0),IF(Itens_B!$D5="mitigacao",IF(Entradas_B!E5="Sim",-Itens_B!$C5,Itens_B!$C5),IF(Itens_B!$D5="evidencia",IF(Entradas_B!E5="Sim",-Itens_B!$C5,0),0)))) | E7: =IF(Entradas_B!F5="N/A",0,IF(Itens_B!$D5="risco",IF(Entradas_B!F5=Itens_B!$E5,Itens_B!$C5,0),IF(Itens_B!$D5="mitigacao",IF(Entradas_B!F5="Sim",-Itens_B!$C5,Itens_B!$C5),IF(Itens_B!$D5="evidencia",IF(Entradas_B!F5="Sim",-Itens_B!$C5,0),0)))) | F7: =IF(Entradas_B!G5="N/A",0,IF(Itens_B!$D5="risco",IF(Entradas_B!G5=Itens_B!$E5,Itens_B!$C5,0),IF(Itens_B!$D5="mitigacao",IF(Entradas_B!G5="Sim",-Itens_B!$C5,Itens_B!$C5),IF(Itens_B!$D5="evidencia",IF(Entradas_B!G5="Sim",-Itens_B!$C5,0),0)))) | G7: =IF(Entradas_B!H5="N/A",0,IF(Itens_B!$D5="risco",IF(Entradas_B!H5=Itens_B!$E5,Itens_B!$C5,0),IF(Itens_B!$D5="mitigacao",IF(Entradas_B!H5="Sim",-Itens_B!$C5,Itens_B!$C5),IF(Itens_B!$D5="evidencia",IF(Entradas_B!H5="Sim",-Itens_B!$C5,0),0)))) | H7: =IF(Entradas_B!I5="N/A",0,IF(Itens_B!$D5="risco",IF(Entradas_B!I5=Itens_B!$E5,Itens_B!$C5,0),IF(Itens_B!$D5="mitigacao",IF(Entradas_B!I5="Sim",-Itens_B!$C5,Itens_B!$C5),IF(Itens_B!$D5="evidencia",IF(Entradas_B!I5="Sim",-Itens_B!$C5,0),0)))) | I7: =IF(Entradas_B!J5="N/A",0,IF(Itens_B!$D5="risco",IF(Entradas_B!J5=Itens_B!$E5,Itens_B!$C5,0),IF(Itens_B!$D5="mitigacao",IF(Entradas_B!J5="Sim",-Itens_B!$C5,Itens_B!$C5),IF(Itens_B!$D5="evidencia",IF(Entradas_B!J5="Sim",-Itens_B!$C5,0),0)))) | ... AF7: =IF(Entradas_B!AG5="N/A",0,IF(Itens_B!$D5="risco",IF(Entradas_B!AG5=Itens_B!$E5,Itens_B!$C5,0),IF(Itens_B!$D5="mitigacao",IF(Entradas_B!AG5="Sim",-Itens_B!$C5,Itens_B!$C5),IF(Itens_B!$D5="evidencia",IF(Entradas_B!AG5="Sim",-Itens_B!$C5,0),0))))
A8: P1.5 | B8: =IF(Entradas_B!C6="N/A",0,IF(Itens_B!$D6="risco",IF(Entradas_B!C6=Itens_B!$E6,Itens_B!$C6,0),IF(Itens_B!$D6="mitigacao",IF(Entradas_B!C6="Sim",-Itens_B!$C6,Itens_B!$C6),IF(Itens_B!$D6="evidencia",IF(Entradas_B!C6="Sim",-Itens_B!$C6,0),0)))) | C8: =IF(Entradas_B!D6="N/A",0,IF(Itens_B!$D6="risco",IF(Entradas_B!D6=Itens_B!$E6,Itens_B!$C6,0),IF(Itens_B!$D6="mitigacao",IF(Entradas_B!D6="Sim",-Itens_B!$C6,Itens_B!$C6),IF(Itens_B!$D6="evidencia",IF(Entradas_B!D6="Sim",-Itens_B!$C6,0),0)))) | D8: =IF(Entradas_B!E6="N/A",0,IF(Itens_B!$D6="risco",IF(Entradas_B!E6=Itens_B!$E6,Itens_B!$C6,0),IF(Itens_B!$D6="mitigacao",IF(Entradas_B!E6="Sim",-Itens_B!$C6,Itens_B!$C6),IF(Itens_B!$D6="evidencia",IF(Entradas_B!E6="Sim",-Itens_B!$C6,0),0)))) | E8: =IF(Entradas_B!F6="N/A",0,IF(Itens_B!$D6="risco",IF(Entradas_B!F6=Itens_B!$E6,Itens_B!$C6,0),IF(Itens_B!$D6="mitigacao",IF(Entradas_B!F6="Sim",-Itens_B!$C6,Itens_B!$C6),IF(Itens_B!$D6="evidencia",IF(Entradas_B!F6="Sim",-Itens_B!$C6,0),0)))) | F8: =IF(Entradas_B!G6="N/A",0,IF(Itens_B!$D6="risco",IF(Entradas_B!G6=Itens_B!$E6,Itens_B!$C6,0),IF(Itens_B!$D6="mitigacao",IF(Entradas_B!G6="Sim",-Itens_B!$C6,Itens_B!$C6),IF(Itens_B!$D6="evidencia",IF(Entradas_B!G6="Sim",-Itens_B!$C6,0),0)))) | G8: =IF(Entradas_B!H6="N/A",0,IF(Itens_B!$D6="risco",IF(Entradas_B!H6=Itens_B!$E6,Itens_B!$C6,0),IF(Itens_B!$D6="mitigacao",IF(Entradas_B!H6="Sim",-Itens_B!$C6,Itens_B!$C6),IF(Itens_B!$D6="evidencia",IF(Entradas_B!H6="Sim",-Itens_B!$C6,0),0)))) | H8: =IF(Entradas_B!I6="N/A",0,IF(Itens_B!$D6="risco",IF(Entradas_B!I6=Itens_B!$E6,Itens_B!$C6,0),IF(Itens_B!$D6="mitigacao",IF(Entradas_B!I6="Sim",-Itens_B!$C6,Itens_B!$C6),IF(Itens_B!$D6="evidencia",IF(Entradas_B!I6="Sim",-Itens_B!$C6,0),0)))) | I8: =IF(Entradas_B!J6="N/A",0,IF(Itens_B!$D6="risco",IF(Entradas_B!J6=Itens_B!$E6,Itens_B!$C6,0),IF(Itens_B!$D6="mitigacao",IF(Entradas_B!J6="Sim",-Itens_B!$C6,Itens_B!$C6),IF(Itens_B!$D6="evidencia",IF(Entradas_B!J6="Sim",-Itens_B!$C6,0),0)))) | ... AF8: =IF(Entradas_B!AG6="N/A",0,IF(Itens_B!$D6="risco",IF(Entradas_B!AG6=Itens_B!$E6,Itens_B!$C6,0),IF(Itens_B!$D6="mitigacao",IF(Entradas_B!AG6="Sim",-Itens_B!$C6,Itens_B!$C6),IF(Itens_B!$D6="evidencia",IF(Entradas_B!AG6="Sim",-Itens_B!$C6,0),0))))
A9: P1.6 | B9: =IF(Entradas_B!C7="N/A",0,IF(Itens_B!$D7="risco",IF(Entradas_B!C7=Itens_B!$E7,Itens_B!$C7,0),IF(Itens_B!$D7="mitigacao",IF(Entradas_B!C7="Sim",-Itens_B!$C7,Itens_B!$C7),IF(Itens_B!$D7="evidencia",IF(Entradas_B!C7="Sim",-Itens_B!$C7,0),0)))) | C9: =IF(Entradas_B!D7="N/A",0,IF(Itens_B!$D7="risco",IF(Entradas_B!D7=Itens_B!$E7,Itens_B!$C7,0),IF(Itens_B!$D7="mitigacao",IF(Entradas_B!D7="Sim",-Itens_B!$C7,Itens_B!$C7),IF(Itens_B!$D7="evidencia",IF(Entradas_B!D7="Sim",-Itens_B!$C7,0),0)))) | D9: =IF(Entradas_B!E7="N/A",0,IF(Itens_B!$D7="risco",IF(Entradas_B!E7=Itens_B!$E7,Itens_B!$C7,0),IF(Itens_B!$D7="mitigacao",IF(Entradas_B!E7="Sim",-Itens_B!$C7,Itens_B!$C7),IF(Itens_B!$D7="evidencia",IF(Entradas_B!E7="Sim",-Itens_B!$C7,0),0)))) | E9: =IF(Entradas_B!F7="N/A",0,IF(Itens_B!$D7="risco",IF(Entradas_B!F7=Itens_B!$E7,Itens_B!$C7,0),IF(Itens_B!$D7="mitigacao",IF(Entradas_B!F7="Sim",-Itens_B!$C7,Itens_B!$C7),IF(Itens_B!$D7="evidencia",IF(Entradas_B!F7="Sim",-Itens_B!$C7,0),0)))) | F9: =IF(Entradas_B!G7="N/A",0,IF(Itens_B!$D7="risco",IF(Entradas_B!G7=Itens_B!$E7,Itens_B!$C7,0),IF(Itens_B!$D7="mitigacao",IF(Entradas_B!G7="Sim",-Itens_B!$C7,Itens_B!$C7),IF(Itens_B!$D7="evidencia",IF(Entradas_B!G7="Sim",-Itens_B!$C7,0),0)))) | G9: =IF(Entradas_B!H7="N/A",0,IF(Itens_B!$D7="risco",IF(Entradas_B!H7=Itens_B!$E7,Itens_B!$C7,0),IF(Itens_B!$D7="mitigacao",IF(Entradas_B!H7="Sim",-Itens_B!$C7,Itens_B!$C7),IF(Itens_B!$D7="evidencia",IF(Entradas_B!H7="Sim",-Itens_B!$C7,0),0)))) | H9: =IF(Entradas_B!I7="N/A",0,IF(Itens_B!$D7="risco",IF(Entradas_B!I7=Itens_B!$E7,Itens_B!$C7,0),IF(Itens_B!$D7="mitigacao",IF(Entradas_B!I7="Sim",-Itens_B!$C7,Itens_B!$C7),IF(Itens_B!$D7="evidencia",IF(Entradas_B!I7="Sim",-Itens_B!$C7,0),0)))) | I9: =IF(Entradas_B!J7="N/A",0,IF(Itens_B!$D7="risco",IF(Entradas_B!J7=Itens_B!$E7,Itens_B!$C7,0),IF(Itens_B!$D7="mitigacao",IF(Entradas_B!J7="Sim",-Itens_B!$C7,Itens_B!$C7),IF(Itens_B!$D7="evidencia",IF(Entradas_B!J7="Sim",-Itens_B!$C7,0),0)))) | ... AF9: =IF(Entradas_B!AG7="N/A",0,IF(Itens_B!$D7="risco",IF(Entradas_B!AG7=Itens_B!$E7,Itens_B!$C7,0),IF(Itens_B!$D7="mitigacao",IF(Entradas_B!AG7="Sim",-Itens_B!$C7,Itens_B!$C7),IF(Itens_B!$D7="evidencia",IF(Entradas_B!AG7="Sim",-Itens_B!$C7,0),0))))
A10: P1.7 | B10: =IF(Entradas_B!C8="N/A",0,IF(Itens_B!$D8="risco",IF(Entradas_B!C8=Itens_B!$E8,Itens_B!$C8,0),IF(Itens_B!$D8="mitigacao",IF(Entradas_B!C8="Sim",-Itens_B!$C8,Itens_B!$C8),IF(Itens_B!$D8="evidencia",IF(Entradas_B!C8="Sim",-Itens_B!$C8,0),0)))) | C10: =IF(Entradas_B!D8="N/A",0,IF(Itens_B!$D8="risco",IF(Entradas_B!D8=Itens_B!$E8,Itens_B!$C8,0),IF(Itens_B!$D8="mitigacao",IF(Entradas_B!D8="Sim",-Itens_B!$C8,Itens_B!$C8),IF(Itens_B!$D8="evidencia",IF(Entradas_B!D8="Sim",-Itens_B!$C8,0),0)))) | D10: =IF(Entradas_B!E8="N/A",0,IF(Itens_B!$D8="risco",IF(Entradas_B!E8=Itens_B!$E8,Itens_B!$C8,0),IF(Itens_B!$D8="mitigacao",IF(Entradas_B!E8="Sim",-Itens_B!$C8,Itens_B!$C8),IF(Itens_B!$D8="evidencia",IF(Entradas_B!E8="Sim",-Itens_B!$C8,0),0)))) | E10: =IF(Entradas_B!F8="N/A",0,IF(Itens_B!$D8="risco",IF(Entradas_B!F8=Itens_B!$E8,Itens_B!$C8,0),IF(Itens_B!$D8="mitigacao",IF(Entradas_B!F8="Sim",-Itens_B!$C8,Itens_B!$C8),IF(Itens_B!$D8="evidencia",IF(Entradas_B!F8="Sim",-Itens_B!$C8,0),0)))) | F10: =IF(Entradas_B!G8="N/A",0,IF(Itens_B!$D8="risco",IF(Entradas_B!G8=Itens_B!$E8,Itens_B!$C8,0),IF(Itens_B!$D8="mitigacao",IF(Entradas_B!G8="Sim",-Itens_B!$C8,Itens_B!$C8),IF(Itens_B!$D8="evidencia",IF(Entradas_B!G8="Sim",-Itens_B!$C8,0),0)))) | G10: =IF(Entradas_B!H8="N/A",0,IF(Itens_B!$D8="risco",IF(Entradas_B!H8=Itens_B!$E8,Itens_B!$C8,0),IF(Itens_B!$D8="mitigacao",IF(Entradas_B!H8="Sim",-Itens_B!$C8,Itens_B!$C8),IF(Itens_B!$D8="evidencia",IF(Entradas_B!H8="Sim",-Itens_B!$C8,0),0)))) | H10: =IF(Entradas_B!I8="N/A",0,IF(Itens_B!$D8="risco",IF(Entradas_B!I8=Itens_B!$E8,Itens_B!$C8,0),IF(Itens_B!$D8="mitigacao",IF(Entradas_B!I8="Sim",-Itens_B!$C8,Itens_B!$C8),IF(Itens_B!$D8="evidencia",IF(Entradas_B!I8="Sim",-Itens_B!$C8,0),0)))) | I10: =IF(Entradas_B!J8="N/A",0,IF(Itens_B!$D8="risco",IF(Entradas_B!J8=Itens_B!$E8,Itens_B!$C8,0),IF(Itens_B!$D8="mitigacao",IF(Entradas_B!J8="Sim",-Itens_B!$C8,Itens_B!$C8),IF(Itens_B!$D8="evidencia",IF(Entradas_B!J8="Sim",-Itens_B!$C8,0),0)))) | ... AF10: =IF(Entradas_B!AG8="N/A",0,IF(Itens_B!$D8="risco",IF(Entradas_B!AG8=Itens_B!$E8,Itens_B!$C8,0),IF(Itens_B!$D8="mitigacao",IF(Entradas_B!AG8="Sim",-Itens_B!$C8,Itens_B!$C8),IF(Itens_B!$D8="evidencia",IF(Entradas_B!AG8="Sim",-Itens_B!$C8,0),0))))
A11: P2.1 | B11: =IF(Entradas_B!C9="N/A",0,IF(Itens_B!$D9="risco",IF(Entradas_B!C9=Itens_B!$E9,Itens_B!$C9,0),IF(Itens_B!$D9="mitigacao",IF(Entradas_B!C9="Sim",-Itens_B!$C9,Itens_B!$C9),IF(Itens_B!$D9="evidencia",IF(Entradas_B!C9="Sim",-Itens_B!$C9,0),0)))) | C11: =IF(Entradas_B!D9="N/A",0,IF(Itens_B!$D9="risco",IF(Entradas_B!D9=Itens_B!$E9,Itens_B!$C9,0),IF(Itens_B!$D9="mitigacao",IF(Entradas_B!D9="Sim",-Itens_B!$C9,Itens_B!$C9),IF(Itens_B!$D9="evidencia",IF(Entradas_B!D9="Sim",-Itens_B!$C9,0),0)))) | D11: =IF(Entradas_B!E9="N/A",0,IF(Itens_B!$D9="risco",IF(Entradas_B!E9=Itens_B!$E9,Itens_B!$C9,0),IF(Itens_B!$D9="mitigacao",IF(Entradas_B!E9="Sim",-Itens_B!$C9,Itens_B!$C9),IF(Itens_B!$D9="evidencia",IF(Entradas_B!E9="Sim",-Itens_B!$C9,0),0)))) | E11: =IF(Entradas_B!F9="N/A",0,IF(Itens_B!$D9="risco",IF(Entradas_B!F9=Itens_B!$E9,Itens_B!$C9,0),IF(Itens_B!$D9="mitigacao",IF(Entradas_B!F9="Sim",-Itens_B!$C9,Itens_B!$C9),IF(Itens_B!$D9="evidencia",IF(Entradas_B!F9="Sim",-Itens_B!$C9,0),0)))) | F11: =IF(Entradas_B!G9="N/A",0,IF(Itens_B!$D9="risco",IF(Entradas_B!G9=Itens_B!$E9,Itens_B!$C9,0),IF(Itens_B!$D9="mitigacao",IF(Entradas_B!G9="Sim",-Itens_B!$C9,Itens_B!$C9),IF(Itens_B!$D9="evidencia",IF(Entradas_B!G9="Sim",-Itens_B!$C9,0),0)))) | G11: =IF(Entradas_B!H9="N/A",0,IF(Itens_B!$D9="risco",IF(Entradas_B!H9=Itens_B!$E9,Itens_B!$C9,0),IF(Itens_B!$D9="mitigacao",IF(Entradas_B!H9="Sim",-Itens_B!$C9,Itens_B!$C9),IF(Itens_B!$D9="evidencia",IF(Entradas_B!H9="Sim",-Itens_B!$C9,0),0)))) | H11: =IF(Entradas_B!I9="N/A",0,IF(Itens_B!$D9="risco",IF(Entradas_B!I9=Itens_B!$E9,Itens_B!$C9,0),IF(Itens_B!$D9="mitigacao",IF(Entradas_B!I9="Sim",-Itens_B!$C9,Itens_B!$C9),IF(Itens_B!$D9="evidencia",IF(Entradas_B!I9="Sim",-Itens_B!$C9,0),0)))) | I11: =IF(Entradas_B!J9="N/A",0,IF(Itens_B!$D9="risco",IF(Entradas_B!J9=Itens_B!$E9,Itens_B!$C9,0),IF(Itens_B!$D9="mitigacao",IF(Entradas_B!J9="Sim",-Itens_B!$C9,Itens_B!$C9),IF(Itens_B!$D9="evidencia",IF(Entradas_B!J9="Sim",-Itens_B!$C9,0),0)))) | ... AF11: =IF(Entradas_B!AG9="N/A",0,IF(Itens_B!$D9="risco",IF(Entradas_B!AG9=Itens_B!$E9,Itens_B!$C9,0),IF(Itens_B!$D9="mitigacao",IF(Entradas_B!AG9="Sim",-Itens_B!$C9,Itens_B!$C9),IF(Itens_B!$D9="evidencia",IF(Entradas_B!AG9="Sim",-Itens_B!$C9,0),0))))
A12: P2.2 | B12: =IF(Entradas_B!C10="N/A",0,IF(Itens_B!$D10="risco",IF(Entradas_B!C10=Itens_B!$E10,Itens_B!$C10,0),IF(Itens_B!$D10="mitigacao",IF(Entradas_B!C10="Sim",-Itens_B!$C10,Itens_B!$C10),IF(Itens_B!$D10="evidencia",IF(Entradas_B!C10="Sim",-Itens_B!$C10,0),0)))) | C12: =IF(Entradas_B!D10="N/A",0,IF(Itens_B!$D10="risco",IF(Entradas_B!D10=Itens_B!$E10,Itens_B!$C10,0),IF(Itens_B!$D10="mitigacao",IF(Entradas_B!D10="Sim",-Itens_B!$C10,Itens_B!$C10),IF(Itens_B!$D10="evidencia",IF(Entradas_B!D10="Sim",-Itens_B!$C10,0),0)))) | D12: =IF(Entradas_B!E10="N/A",0,IF(Itens_B!$D10="risco",IF(Entradas_B!E10=Itens_B!$E10,Itens_B!$C10,0),IF(Itens_B!$D10="mitigacao",IF(Entradas_B!E10="Sim",-Itens_B!$C10,Itens_B!$C10),IF(Itens_B!$D10="evidencia",IF(Entradas_B!E10="Sim",-Itens_B!$C10,0),0)))) | E12: =IF(Entradas_B!F10="N/A",0,IF(Itens_B!$D10="risco",IF(Entradas_B!F10=Itens_B!$E10,Itens_B!$C10,0),IF(Itens_B!$D10="mitigacao",IF(Entradas_B!F10="Sim",-Itens_B!$C10,Itens_B!$C10),IF(Itens_B!$D10="evidencia",IF(Entradas_B!F10="Sim",-Itens_B!$C10,0),0)))) | F12: =IF(Entradas_B!G10="N/A",0,IF(Itens_B!$D10="risco",IF(Entradas_B!G10=Itens_B!$E10,Itens_B!$C10,0),IF(Itens_B!$D10="mitigacao",IF(Entradas_B!G10="Sim",-Itens_B!$C10,Itens_B!$C10),IF(Itens_B!$D10="evidencia",IF(Entradas_B!G10="Sim",-Itens_B!$C10,0),0)))) | G12: =IF(Entradas_B!H10="N/A",0,IF(Itens_B!$D10="risco",IF(Entradas_B!H10=Itens_B!$E10,Itens_B!$C10,0),IF(Itens_B!$D10="mitigacao",IF(Entradas_B!H10="Sim",-Itens_B!$C10,Itens_B!$C10),IF(Itens_B!$D10="evidencia",IF(Entradas_B!H10="Sim",-Itens_B!$C10,0),0)))) | H12: =IF(Entradas_B!I10="N/A",0,IF(Itens_B!$D10="risco",IF(Entradas_B!I10=Itens_B!$E10,Itens_B!$C10,0),IF(Itens_B!$D10="mitigacao",IF(Entradas_B!I10="Sim",-Itens_B!$C10,Itens_B!$C10),IF(Itens_B!$D10="evidencia",IF(Entradas_B!I10="Sim",-Itens_B!$C10,0),0)))) | I12: =IF(Entradas_B!J10="N/A",0,IF(Itens_B!$D10="risco",IF(Entradas_B!J10=Itens_B!$E10,Itens_B!$C10,0),IF(Itens_B!$D10="mitigacao",IF(Entradas_B!J10="Sim",-Itens_B!$C10,Itens_B!$C10),IF(Itens_B!$D10="evidencia",IF(Entradas_B!J10="Sim",-Itens_B!$C10,0),0)))) | ... AF12: =IF(Entradas_B!AG10="N/A",0,IF(Itens_B!$D10="risco",IF(Entradas_B!AG10=Itens_B!$E10,Itens_B!$C10,0),IF(Itens_B!$D10="mitigacao",IF(Entradas_B!AG10="Sim",-Itens_B!$C10,Itens_B!$C10),IF(Itens_B!$D10="evidencia",IF(Entradas_B!AG10="Sim",-Itens_B!$C10,0),0))))
A13: P2.3 | B13: =IF(Entradas_B!C11="N/A",0,IF(Itens_B!$D11="risco",IF(Entradas_B!C11=Itens_B!$E11,Itens_B!$C11,0),IF(Itens_B!$D11="mitigacao",IF(Entradas_B!C11="Sim",-Itens_B!$C11,Itens_B!$C11),IF(Itens_B!$D11="evidencia",IF(Entradas_B!C11="Sim",-Itens_B!$C11,0),0)))) | C13: =IF(Entradas_B!D11="N/A",0,IF(Itens_B!$D11="risco",IF(Entradas_B!D11=Itens_B!$E11,Itens_B!$C11,0),IF(Itens_B!$D11="mitigacao",IF(Entradas_B!D11="Sim",-Itens_B!$C11,Itens_B!$C11),IF(Itens_B!$D11="evidencia",IF(Entradas_B!D11="Sim",-Itens_B!$C11,0),0)))) | D13: =IF(Entradas_B!E11="N/A",0,IF(Itens_B!$D11="risco",IF(Entradas_B!E11=Itens_B!$E11,Itens_B!$C11,0),IF(Itens_B!$D11="mitigacao",IF(Entradas_B!E11="Sim",-Itens_B!$C11,Itens_B!$C11),IF(Itens_B!$D11="evidencia",IF(Entradas_B!E11="Sim",-Itens_B!$C11,0),0)))) | E13: =IF(Entradas_B!F11="N/A",0,IF(Itens_B!$D11="risco",IF(Entradas_B!F11=Itens_B!$E11,Itens_B!$C11,0),IF(Itens_B!$D11="mitigacao",IF(Entradas_B!F11="Sim",-Itens_B!$C11,Itens_B!$C11),IF(Itens_B!$D11="evidencia",IF(Entradas_B!F11="Sim",-Itens_B!$C11,0),0)))) | F13: =IF(Entradas_B!G11="N/A",0,IF(Itens_B!$D11="risco",IF(Entradas_B!G11=Itens_B!$E11,Itens_B!$C11,0),IF(Itens_B!$D11="mitigacao",IF(Entradas_B!G11="Sim",-Itens_B!$C11,Itens_B!$C11),IF(Itens_B!$D11="evidencia",IF(Entradas_B!G11="Sim",-Itens_B!$C11,0),0)))) | G13: =IF(Entradas_B!H11="N/A",0,IF(Itens_B!$D11="risco",IF(Entradas_B!H11=Itens_B!$E11,Itens_B!$C11,0),IF(Itens_B!$D11="mitigacao",IF(Entradas_B!H11="Sim",-Itens_B!$C11,Itens_B!$C11),IF(Itens_B!$D11="evidencia",IF(Entradas_B!H11="Sim",-Itens_B!$C11,0),0)))) | H13: =IF(Entradas_B!I11="N/A",0,IF(Itens_B!$D11="risco",IF(Entradas_B!I11=Itens_B!$E11,Itens_B!$C11,0),IF(Itens_B!$D11="mitigacao",IF(Entradas_B!I11="Sim",-Itens_B!$C11,Itens_B!$C11),IF(Itens_B!$D11="evidencia",IF(Entradas_B!I11="Sim",-Itens_B!$C11,0),0)))) | I13: =IF(Entradas_B!J11="N/A",0,IF(Itens_B!$D11="risco",IF(Entradas_B!J11=Itens_B!$E11,Itens_B!$C11,0),IF(Itens_B!$D11="mitigacao",IF(Entradas_B!J11="Sim",-Itens_B!$C11,Itens_B!$C11),IF(Itens_B!$D11="evidencia",IF(Entradas_B!J11="Sim",-Itens_B!$C11,0),0)))) | ... AF13: =IF(Entradas_B!AG11="N/A",0,IF(Itens_B!$D11="risco",IF(Entradas_B!AG11=Itens_B!$E11,Itens_B!$C11,0),IF(Itens_B!$D11="mitigacao",IF(Entradas_B!AG11="Sim",-Itens_B!$C11,Itens_B!$C11),IF(Itens_B!$D11="evidencia",IF(Entradas_B!AG11="Sim",-Itens_B!$C11,0),0))))
A14: P2.4 | B14: =IF(Entradas_B!C12="N/A",0,IF(Itens_B!$D12="risco",IF(Entradas_B!C12=Itens_B!$E12,Itens_B!$C12,0),IF(Itens_B!$D12="mitigacao",IF(Entradas_B!C12="Sim",-Itens_B!$C12,Itens_B!$C12),IF(Itens_B!$D12="evidencia",IF(Entradas_B!C12="Sim",-Itens_B!$C12,0),0)))) | C14: =IF(Entradas_B!D12="N/A",0,IF(Itens_B!$D12="risco",IF(Entradas_B!D12=Itens_B!$E12,Itens_B!$C12,0),IF(Itens_B!$D12="mitigacao",IF(Entradas_B!D12="Sim",-Itens_B!$C12,Itens_B!$C12),IF(Itens_B!$D12="evidencia",IF(Entradas_B!D12="Sim",-Itens_B!$C12,0),0)))) | D14: =IF(Entradas_B!E12="N/A",0,IF(Itens_B!$D12="risco",IF(Entradas_B!E12=Itens_B!$E12,Itens_B!$C12,0),IF(Itens_B!$D12="mitigacao",IF(Entradas_B!E12="Sim",-Itens_B!$C12,Itens_B!$C12),IF(Itens_B!$D12="evidencia",IF(Entradas_B!E12="Sim",-Itens_B!$C12,0),0)))) | E14: =IF(Entradas_B!F12="N/A",0,IF(Itens_B!$D12="risco",IF(Entradas_B!F12=Itens_B!$E12,Itens_B!$C12,0),IF(Itens_B!$D12="mitigacao",IF(Entradas_B!F12="Sim",-Itens_B!$C12,Itens_B!$C12),IF(Itens_B!$D12="evidencia",IF(Entradas_B!F12="Sim",-Itens_B!$C12,0),0)))) | F14: =IF(Entradas_B!G12="N/A",0,IF(Itens_B!$D12="risco",IF(Entradas_B!G12=Itens_B!$E12,Itens_B!$C12,0),IF(Itens_B!$D12="mitigacao",IF(Entradas_B!G12="Sim",-Itens_B!$C12,Itens_B!$C12),IF(Itens_B!$D12="evidencia",IF(Entradas_B!G12="Sim",-Itens_B!$C12,0),0)))) | G14: =IF(Entradas_B!H12="N/A",0,IF(Itens_B!$D12="risco",IF(Entradas_B!H12=Itens_B!$E12,Itens_B!$C12,0),IF(Itens_B!$D12="mitigacao",IF(Entradas_B!H12="Sim",-Itens_B!$C12,Itens_B!$C12),IF(Itens_B!$D12="evidencia",IF(Entradas_B!H12="Sim",-Itens_B!$C12,0),0)))) | H14: =IF(Entradas_B!I12="N/A",0,IF(Itens_B!$D12="risco",IF(Entradas_B!I12=Itens_B!$E12,Itens_B!$C12,0),IF(Itens_B!$D12="mitigacao",IF(Entradas_B!I12="Sim",-Itens_B!$C12,Itens_B!$C12),IF(Itens_B!$D12="evidencia",IF(Entradas_B!I12="Sim",-Itens_B!$C12,0),0)))) | I14: =IF(Entradas_B!J12="N/A",0,IF(Itens_B!$D12="risco",IF(Entradas_B!J12=Itens_B!$E12,Itens_B!$C12,0),IF(Itens_B!$D12="mitigacao",IF(Entradas_B!J12="Sim",-Itens_B!$C12,Itens_B!$C12),IF(Itens_B!$D12="evidencia",IF(Entradas_B!J12="Sim",-Itens_B!$C12,0),0)))) | ... AF14: =IF(Entradas_B!AG12="N/A",0,IF(Itens_B!$D12="risco",IF(Entradas_B!AG12=Itens_B!$E12,Itens_B!$C12,0),IF(Itens_B!$D12="mitigacao",IF(Entradas_B!AG12="Sim",-Itens_B!$C12,Itens_B!$C12),IF(Itens_B!$D12="evidencia",IF(Entradas_B!AG12="Sim",-Itens_B!$C12,0),0))))
A15: P2.5 | B15: =IF(Entradas_B!C13="N/A",0,IF(Itens_B!$D13="risco",IF(Entradas_B!C13=Itens_B!$E13,Itens_B!$C13,0),IF(Itens_B!$D13="mitigacao",IF(Entradas_B!C13="Sim",-Itens_B!$C13,Itens_B!$C13),IF(Itens_B!$D13="evidencia",IF(Entradas_B!C13="Sim",-Itens_B!$C13,0),0)))) | C15: =IF(Entradas_B!D13="N/A",0,IF(Itens_B!$D13="risco",IF(Entradas_B!D13=Itens_B!$E13,Itens_B!$C13,0),IF(Itens_B!$D13="mitigacao",IF(Entradas_B!D13="Sim",-Itens_B!$C13,Itens_B!$C13),IF(Itens_B!$D13="evidencia",IF(Entradas_B!D13="Sim",-Itens_B!$C13,0),0)))) | D15: =IF(Entradas_B!E13="N/A",0,IF(Itens_B!$D13="risco",IF(Entradas_B!E13=Itens_B!$E13,Itens_B!$C13,0),IF(Itens_B!$D13="mitigacao",IF(Entradas_B!E13="Sim",-Itens_B!$C13,Itens_B!$C13),IF(Itens_B!$D13="evidencia",IF(Entradas_B!E13="Sim",-Itens_B!$C13,0),0)))) | E15: =IF(Entradas_B!F13="N/A",0,IF(Itens_B!$D13="risco",IF(Entradas_B!F13=Itens_B!$E13,Itens_B!$C13,0),IF(Itens_B!$D13="mitigacao",IF(Entradas_B!F13="Sim",-Itens_B!$C13,Itens_B!$C13),IF(Itens_B!$D13="evidencia",IF(Entradas_B!F13="Sim",-Itens_B!$C13,0),0)))) | F15: =IF(Entradas_B!G13="N/A",0,IF(Itens_B!$D13="risco",IF(Entradas_B!G13=Itens_B!$E13,Itens_B!$C13,0),IF(Itens_B!$D13="mitigacao",IF(Entradas_B!G13="Sim",-Itens_B!$C13,Itens_B!$C13),IF(Itens_B!$D13="evidencia",IF(Entradas_B!G13="Sim",-Itens_B!$C13,0),0)))) | G15: =IF(Entradas_B!H13="N/A",0,IF(Itens_B!$D13="risco",IF(Entradas_B!H13=Itens_B!$E13,Itens_B!$C13,0),IF(Itens_B!$D13="mitigacao",IF(Entradas_B!H13="Sim",-Itens_B!$C13,Itens_B!$C13),IF(Itens_B!$D13="evidencia",IF(Entradas_B!H13="Sim",-Itens_B!$C13,0),0)))) | H15: =IF(Entradas_B!I13="N/A",0,IF(Itens_B!$D13="risco",IF(Entradas_B!I13=Itens_B!$E13,Itens_B!$C13,0),IF(Itens_B!$D13="mitigacao",IF(Entradas_B!I13="Sim",-Itens_B!$C13,Itens_B!$C13),IF(Itens_B!$D13="evidencia",IF(Entradas_B!I13="Sim",-Itens_B!$C13,0),0)))) | I15: =IF(Entradas_B!J13="N/A",0,IF(Itens_B!$D13="risco",IF(Entradas_B!J13=Itens_B!$E13,Itens_B!$C13,0),IF(Itens_B!$D13="mitigacao",IF(Entradas_B!J13="Sim",-Itens_B!$C13,Itens_B!$C13),IF(Itens_B!$D13="evidencia",IF(Entradas_B!J13="Sim",-Itens_B!$C13,0),0)))) | ... AF15: =IF(Entradas_B!AG13="N/A",0,IF(Itens_B!$D13="risco",IF(Entradas_B!AG13=Itens_B!$E13,Itens_B!$C13,0),IF(Itens_B!$D13="mitigacao",IF(Entradas_B!AG13="Sim",-Itens_B!$C13,Itens_B!$C13),IF(Itens_B!$D13="evidencia",IF(Entradas_B!AG13="Sim",-Itens_B!$C13,0),0))))
... A74: P7.14 | B74: =IF(Entradas_B!C72="N/A",0,IF(Itens_B!$D72="risco",IF(Entradas_B!C72=Itens_B!$E72,Itens_B!$C72,0),IF(Itens_B!$D72="mitigacao",IF(Entradas_B!C72="Sim",-Itens_B!$C72,Itens_B!$C72),IF(Itens_B!$D72="evidencia",IF(Entradas_B!C72="Sim",-Itens_B!$C72,0),0)))) | C74: =IF(Entradas_B!D72="N/A",0,IF(Itens_B!$D72="risco",IF(Entradas_B!D72=Itens_B!$E72,Itens_B!$C72,0),IF(Itens_B!$D72="mitigacao",IF(Entradas_B!D72="Sim",-Itens_B!$C72,Itens_B!$C72),IF(Itens_B!$D72="evidencia",IF(Entradas_B!D72="Sim",-Itens_B!$C72,0),0)))) | D74: =IF(Entradas_B!E72="N/A",0,IF(Itens_B!$D72="risco",IF(Entradas_B!E72=Itens_B!$E72,Itens_B!$C72,0),IF(Itens_B!$D72="mitigacao",IF(Entradas_B!E72="Sim",-Itens_B!$C72,Itens_B!$C72),IF(Itens_B!$D72="evidencia",IF(Entradas_B!E72="Sim",-Itens_B!$C72,0),0)))) | E74: =IF(Entradas_B!F72="N/A",0,IF(Itens_B!$D72="risco",IF(Entradas_B!F72=Itens_B!$E72,Itens_B!$C72,0),IF(Itens_B!$D72="mitigacao",IF(Entradas_B!F72="Sim",-Itens_B!$C72,Itens_B!$C72),IF(Itens_B!$D72="evidencia",IF(Entradas_B!F72="Sim",-Itens_B!$C72,0),0)))) | F74: =IF(Entradas_B!G72="N/A",0,IF(Itens_B!$D72="risco",IF(Entradas_B!G72=Itens_B!$E72,Itens_B!$C72,0),IF(Itens_B!$D72="mitigacao",IF(Entradas_B!G72="Sim",-Itens_B!$C72,Itens_B!$C72),IF(Itens_B!$D72="evidencia",IF(Entradas_B!G72="Sim",-Itens_B!$C72,0),0)))) | G74: =IF(Entradas_B!H72="N/A",0,IF(Itens_B!$D72="risco",IF(Entradas_B!H72=Itens_B!$E72,Itens_B!$C72,0),IF(Itens_B!$D72="mitigacao",IF(Entradas_B!H72="Sim",-Itens_B!$C72,Itens_B!$C72),IF(Itens_B!$D72="evidencia",IF(Entradas_B!H72="Sim",-Itens_B!$C72,0),0)))) | H74: =IF(Entradas_B!I72="N/A",0,IF(Itens_B!$D72="risco",IF(Entradas_B!I72=Itens_B!$E72,Itens_B!$C72,0),IF(Itens_B!$D72="mitigacao",IF(Entradas_B!I72="Sim",-Itens_B!$C72,Itens_B!$C72),IF(Itens_B!$D72="evidencia",IF(Entradas_B!I72="Sim",-Itens_B!$C72,0),0)))) | I74: =IF(Entradas_B!J72="N/A",0,IF(Itens_B!$D72="risco",IF(Entradas_B!J72=Itens_B!$E72,Itens_B!$C72,0),IF(Itens_B!$D72="mitigacao",IF(Entradas_B!J72="Sim",-Itens_B!$C72,Itens_B!$C72),IF(Itens_B!$D72="evidencia",IF(Entradas_B!J72="Sim",-Itens_B!$C72,0),0)))) | ... AF74: =IF(Entradas_B!AG72="N/A",0,IF(Itens_B!$D72="risco",IF(Entradas_B!AG72=Itens_B!$E72,Itens_B!$C72,0),IF(Itens_B!$D72="mitigacao",IF(Entradas_B!AG72="Sim",-Itens_B!$C72,Itens_B!$C72),IF(Itens_B!$D72="evidencia",IF(Entradas_B!AG72="Sim",-Itens_B!$C72,0),0))))
A75: Subtotal Bloco 1 | B75: =SUMIF(Itens_B!$B$2:$B$72,"1",B$4:B$74) | C75: =SUMIF(Itens_B!$B$2:$B$72,"1",C$4:C$74) | D75: =SUMIF(Itens_B!$B$2:$B$72,"1",D$4:D$74) | E75: =SUMIF(Itens_B!$B$2:$B$72,"1",E$4:E$74) | F75: =SUMIF(Itens_B!$B$2:$B$72,"1",F$4:F$74) | G75: =SUMIF(Itens_B!$B$2:$B$72,"1",G$4:G$74) | H75: =SUMIF(Itens_B!$B$2:$B$72,"1",H$4:H$74) | I75: =SUMIF(Itens_B!$B$2:$B$72,"1",I$4:I$74) | ... AF75: =SUMIF(Itens_B!$B$2:$B$72,"1",AF$4:AF$74)
A76: Subtotal Bloco 2 | B76: =SUMIF(Itens_B!$B$2:$B$72,"2",B$4:B$74) | C76: =SUMIF(Itens_B!$B$2:$B$72,"2",C$4:C$74) | D76: =SUMIF(Itens_B!$B$2:$B$72,"2",D$4:D$74) | E76: =SUMIF(Itens_B!$B$2:$B$72,"2",E$4:E$74) | F76: =SUMIF(Itens_B!$B$2:$B$72,"2",F$4:F$74) | G76: =SUMIF(Itens_B!$B$2:$B$72,"2",G$4:G$74) | H76: =SUMIF(Itens_B!$B$2:$B$72,"2",H$4:H$74) | I76: =SUMIF(Itens_B!$B$2:$B$72,"2",I$4:I$74) | ... AF76: =SUMIF(Itens_B!$B$2:$B$72,"2",AF$4:AF$74)
A77: Subtotal Bloco 3 | B77: =SUMIF(Itens_B!$B$2:$B$72,"3",B$4:B$74) | C77: =SUMIF(Itens_B!$B$2:$B$72,"3",C$4:C$74) | D77: =SUMIF(Itens_B!$B$2:$B$72,"3",D$4:D$74) | E77: =SUMIF(Itens_B!$B$2:$B$72,"3",E$4:E$74) | F77: =SUMIF(Itens_B!$B$2:$B$72,"3",F$4:F$74) | G77: =SUMIF(Itens_B!$B$2:$B$72,"3",G$4:G$74) | H77: =SUMIF(Itens_B!$B$2:$B$72,"3",H$4:H$74) | I77: =SUMIF(Itens_B!$B$2:$B$72,"3",I$4:I$74) | ... AF77: =SUMIF(Itens_B!$B$2:$B$72,"3",AF$4:AF$74)
A78: Subtotal Bloco 4 | B78: =SUMIF(Itens_B!$B$2:$B$72,"4",B$4:B$74) | C78: =SUMIF(Itens_B!$B$2:$B$72,"4",C$4:C$74) | D78: =SUMIF(Itens_B!$B$2:$B$72,"4",D$4:D$74) | E78: =SUMIF(Itens_B!$B$2:$B$72,"4",E$4:E$74) | F78: =SUMIF(Itens_B!$B$2:$B$72,"4",F$4:F$74) | G78: =SUMIF(Itens_B!$B$2:$B$72,"4",G$4:G$74) | H78: =SUMIF(Itens_B!$B$2:$B$72,"4",H$4:H$74) | I78: =SUMIF(Itens_B!$B$2:$B$72,"4",I$4:I$74) | ... AF78: =SUMIF(Itens_B!$B$2:$B$72,"4",AF$4:AF$74)
A79: Subtotal Bloco 5 | B79: =SUMIF(Itens_B!$B$2:$B$72,"5",B$4:B$74) | C79: =SUMIF(Itens_B!$B$2:$B$72,"5",C$4:C$74) | D79: =SUMIF(Itens_B!$B$2:$B$72,"5",D$4:D$74) | E79: =SUMIF(Itens_B!$B$2:$B$72,"5",E$4:E$74) | F79: =SUMIF(Itens_B!$B$2:$B$72,"5",F$4:F$74) | G79: =SUMIF(Itens_B!$B$2:$B$72,"5",G$4:G$74) | H79: =SUMIF(Itens_B!$B$2:$B$72,"5",H$4:H$74) | I79: =SUMIF(Itens_B!$B$2:$B$72,"5",I$4:I$74) | ... AF79: =SUMIF(Itens_B!$B$2:$B$72,"5",AF$4:AF$74)
A80: Subtotal Bloco 6 | B80: =SUMIF(Itens_B!$B$2:$B$72,"6",B$4:B$74) | C80: =SUMIF(Itens_B!$B$2:$B$72,"6",C$4:C$74) | D80: =SUMIF(Itens_B!$B$2:$B$72,"6",D$4:D$74) | E80: =SUMIF(Itens_B!$B$2:$B$72,"6",E$4:E$74) | F80: =SUMIF(Itens_B!$B$2:$B$72,"6",F$4:F$74) | G80: =SUMIF(Itens_B!$B$2:$B$72,"6",G$4:G$74) | H80: =SUMIF(Itens_B!$B$2:$B$72,"6",H$4:H$74) | I80: =SUMIF(Itens_B!$B$2:$B$72,"6",I$4:I$74) | ... AF80: =SUMIF(Itens_B!$B$2:$B$72,"6",AF$4:AF$74)
A81: Subtotal Bloco 6.b | B81: =SUMIF(Itens_B!$B$2:$B$72,"6.b",B$4:B$74) | C81: =SUMIF(Itens_B!$B$2:$B$72,"6.b",C$4:C$74) | D81: =SUMIF(Itens_B!$B$2:$B$72,"6.b",D$4:D$74) | E81: =SUMIF(Itens_B!$B$2:$B$72,"6.b",E$4:E$74) | F81: =SUMIF(Itens_B!$B$2:$B$72,"6.b",F$4:F$74) | G81: =SUMIF(Itens_B!$B$2:$B$72,"6.b",G$4:G$74) | H81: =SUMIF(Itens_B!$B$2:$B$72,"6.b",H$4:H$74) | I81: =SUMIF(Itens_B!$B$2:$B$72,"6.b",I$4:I$74) | ... AF81: =SUMIF(Itens_B!$B$2:$B$72,"6.b",AF$4:AF$74)
A82: Bloco 7 raw (antes do clamp) | B82: =SUMIF(Itens_B!$B$2:$B$72,"7",B$4:B$74) | C82: =SUMIF(Itens_B!$B$2:$B$72,"7",C$4:C$74) | D82: =SUMIF(Itens_B!$B$2:$B$72,"7",D$4:D$74) | E82: =SUMIF(Itens_B!$B$2:$B$72,"7",E$4:E$74) | F82: =SUMIF(Itens_B!$B$2:$B$72,"7",F$4:F$74) | G82: =SUMIF(Itens_B!$B$2:$B$72,"7",G$4:G$74) | H82: =SUMIF(Itens_B!$B$2:$B$72,"7",H$4:H$74) | I82: =SUMIF(Itens_B!$B$2:$B$72,"7",I$4:I$74) | ... AF82: =SUMIF(Itens_B!$B$2:$B$72,"7",AF$4:AF$74)
A83: Bloco 7 (clamp piso 0 — A1) | B83: =MAX(0,B82) | C83: =MAX(0,C82) | D83: =MAX(0,D82) | E83: =MAX(0,E82) | F83: =MAX(0,F82) | G83: =MAX(0,G82) | H83: =MAX(0,H82) | I83: =MAX(0,I82) | ... AF83: =MAX(0,AF82)
A84: TOTAL (6.b só se ativado) | B84: =B75+B76+B77+B78+B79+B80+B83+IF(B$2="sim",B81,0) | C84: =C75+C76+C77+C78+C79+C80+C83+IF(C$2="sim",C81,0) | D84: =D75+D76+D77+D78+D79+D80+D83+IF(D$2="sim",D81,0) | E84: =E75+E76+E77+E78+E79+E80+E83+IF(E$2="sim",E81,0) | F84: =F75+F76+F77+F78+F79+F80+F83+IF(F$2="sim",F81,0) | G84: =G75+G76+G77+G78+G79+G80+G83+IF(G$2="sim",G81,0) | H84: =H75+H76+H77+H78+H79+H80+H83+IF(H$2="sim",H81,0) | I84: =I75+I76+I77+I78+I79+I80+I83+IF(I$2="sim",I81,0) | ... AF84: =AF75+AF76+AF77+AF78+AF79+AF80+AF83+IF(AF$2="sim",AF81,0)
A85: Nível por faixa (cortes 58/127/208 · 64/141/230) | B85: =IF(B84<=IF(B$2="sim",64,58),"I",IF(B84<=IF(B$2="sim",141,127),"II",IF(B84<=IF(B$2="sim",230,208),"III","IV")))) | C85: =IF(C84<=IF(C$2="sim",64,58),"I",IF(C84<=IF(C$2="sim",141,127),"II",IF(C84<=IF(C$2="sim",230,208),"III","IV")))) | D85: =IF(D84<=IF(D$2="sim",64,58),"I",IF(D84<=IF(D$2="sim",141,127),"II",IF(D84<=IF(D$2="sim",230,208),"III","IV")))) | E85: =IF(E84<=IF(E$2="sim",64,58),"I",IF(E84<=IF(E$2="sim",141,127),"II",IF(E84<=IF(E$2="sim",230,208),"III","IV")))) | F85: =IF(F84<=IF(F$2="sim",64,58),"I",IF(F84<=IF(F$2="sim",141,127),"II",IF(F84<=IF(F$2="sim",230,208),"III","IV")))) | G85: =IF(G84<=IF(G$2="sim",64,58),"I",IF(G84<=IF(G$2="sim",141,127),"II",IF(G84<=IF(G$2="sim",230,208),"III","IV")))) | H85: =IF(H84<=IF(H$2="sim",64,58),"I",IF(H84<=IF(H$2="sim",141,127),"II",IF(H84<=IF(H$2="sim",230,208),"III","IV")))) | I85: =IF(I84<=IF(I$2="sim",64,58),"I",IF(I84<=IF(I$2="sim",141,127),"II",IF(I84<=IF(I$2="sim",230,208),"III","IV")))) | ... AF85: =IF(AF84<=IF(AF$2="sim",64,58),"I",IF(AF84<=IF(AF$2="sim",141,127),"II",IF(AF84<=IF(AF$2="sim",230,208),"III","IV"))))
A86: Resultado final esperado (com overrides — A4) | B86: I | C86: I | D86: II | E86: II | F86: II | G86: III | H86: III | I86: III | J86: IV | K86: IV | L86: I | M86: I | N86: II | O86: II | P86: III | Q86: III | R86: IV | S86: IV | T86: não avaliável | U86: não avaliável | V86: I | W86: I | X86: I | Y86: IV | Z86: IV (Prevalência) | AA86: não avaliável | AB86: não avaliável (devolução) | AC86: não avaliável (devolução) | AD86: não avaliável (devolução) | AE86: não avaliável (devolução) | AF86: II
A87: Escore app (preencher na v2.0-draft)
A88: Nível/resultado app
A89: Δ (deve ser 0 / idêntico)

Sheet V17_VersaoA
A1: Linha | B1: Eixo | C1: Perguntas de risco (v2) | D1: Respostas de risco | E1: Resultado esperado | F1: Nota
A2: V17-1.0 | B2: Eixo 1 — natureza e autonomia | C2: 8 | D2: 0 | E2: Nível I
A3: V17-1.1 | B3: Eixo 1 — natureza e autonomia | C3: 8 | D3: 1 | E3: Nível II
A4: V17-1.2 | B4: Eixo 1 — natureza e autonomia | C4: 8 | D4: 2 | E4: Nível II
A5: V17-1.3 | B5: Eixo 1 — natureza e autonomia | C5: 8 | D5: 3 | E5: Nível III
A6: V17-1.4 | B6: Eixo 1 — natureza e autonomia | C6: 8 | D6: 4 | E6: Nível III
A7: V17-1.5 | B7: Eixo 1 — natureza e autonomia | C7: 8 | D7: 5+ | E7: Nível IV
A8: V17-2.0 | B8: Eixo 2 — impacto (v2) | C8: 12 | D8: 0 | E8: Nível I | F8: corte absoluto mantido (D-1)
A9: V17-2.1 | B9: Eixo 2 — impacto (v2) | C9: 12 | D9: 1 | E9: Nível II | F9: corte absoluto mantido (D-1)
A10: V17-2.2 | B10: Eixo 2 — impacto (v2) | C10: 12 | D10: 2 | E10: Nível II | F10: corte absoluto mantido (D-1)
A11: V17-2.3 | B11: Eixo 2 — impacto (v2) | C11: 12 | D11: 3 | E11: Nível III | F11: corte absoluto mantido (D-1)
A12: V17-2.4 | B12: Eixo 2 — impacto (v2) | C12: 12 | D12: 4 | E12: Nível III | F12: corte absoluto mantido (D-1)
A13: V17-2.5 | B13: Eixo 2 — impacto (v2) | C13: 12 | D13: 5+ | E13: Nível IV | F13: corte absoluto mantido (D-1)
A14: V17-3.0 | B14: Eixo 3 — dados (v2) | C14: 13 | D14: 0 | E14: Nível I | F14: corte absoluto mantido (D-1)
A15: V17-3.1 | B15: Eixo 3 — dados (v2) | C15: 13 | D15: 1 | E15: Nível II | F15: corte absoluto mantido (D-1)
A16: V17-3.2 | B16: Eixo 3 — dados (v2) | C16: 13 | D16: 2 | E16: Nível II | F16: corte absoluto mantido (D-1)
A17: V17-3.3 | B17: Eixo 3 — dados (v2) | C17: 13 | D17: 3 | E17: Nível III | F17: corte absoluto mantido (D-1)
A18: V17-3.4 | B18: Eixo 3 — dados (v2) | C18: 13 | D18: 4 | E18: Nível III | F18: corte absoluto mantido (D-1)
A19: V17-3.5 | B19: Eixo 3 — dados (v2) | C19: 13 | D19: 5+ | E19: Nível IV | F19: corte absoluto mantido (D-1)
A20: V17-4.0 | B20: Eixo 4 — representatividade | C20: 8 | D20: 0 | E20: Nível I
A21: V17-4.1 | B21: Eixo 4 — representatividade | C21: 8 | D21: 1 | E21: Nível II
A22: V17-4.2 | B22: Eixo 4 — representatividade | C22: 8 | D22: 2 | E22: Nível II
A23: V17-4.3 | B23: Eixo 4 — representatividade | C23: 8 | D23: 3 | E23: Nível III
A24: V17-4.4 | B24: Eixo 4 — representatividade | C24: 8 | D24: 4 | E24: Nível III
A25: V17-4.5 | B25: Eixo 4 — representatividade | C25: 8 | D25: 5+ | E25: Nível IV
A26: V17-5.0 | B26: Eixo 5 — supervisão | C26: 8 | D26: 0 | E26: Nível I
A27: V17-5.1 | B27: Eixo 5 — supervisão | C27: 8 | D27: 1 | E27: Nível II
A28: V17-5.2 | B28: Eixo 5 — supervisão | C28: 8 | D28: 2 | E28: Nível II
A29: V17-5.3 | B29: Eixo 5 — supervisão | C29: 8 | D29: 3 | E29: Nível III
A30: V17-5.4 | B30: Eixo 5 — supervisão | C30: 8 | D30: 4 | E30: Nível III
A31: V17-5.5 | B31: Eixo 5 — supervisão | C31: 8 | D31: 5+ | E31: Nível IV
A32: V17-3b.0 | B32: Eixo 3.b (regra especial) | C32: 6 | D32: 0 | E32: não eleva o consolidado
A33: V17-3b.1 | B33: Eixo 3.b | C33: 6 | D33: 1 | E33: eleva para Nível III
A34: V17-3b.2 | B34: Eixo 3.b | C34: 6 | D34: 2 | E34: eleva para Nível III
A35: V17-3b.3 | B35: Eixo 3.b | C35: 6 | D35: 3+ | E35: eleva para Nível IV
A36: V17-3b.5 | B36: Eixo 3.b — 3.b.2 = 'Não' | D36: — | E36: não avaliável | F36: eliminatória (anuência ausente)
A37: V17-3b.6 | B37: Eixo 3.b — 3.b.4.1/3.b.7 falhas | D37: — | E37: não avaliável (devolução) | F37: diligências não contam como resposta de risco
A38: V17-C.1 | B38: Consolidação (regra do máximo) | D38: eixos {I, II, I, III, I} | E38: Nível III | F38: pior eixo prevalece
A39: V17-C.2 | B39: Consolidação | D39: qualquer eixo em IV | E39: Nível IV
A40: V17-C.3 | B40: Consolidação + 3.b | D40: 3.b com 2 respostas, demais em I | E40: Nível III | F40: regra especial do 3.b

Sheet V18_MapaIDs
A1: Elemento | B1: ID v1 (data.ts atual) | C1: ID v2 (spec) | D1: Resultado esperado | E1: Status
A2: descritiva 1 (pergunta do sistema) | B2: contexto1 | C2: C.1 | D2: remapeado 1:1, sem reinterpretação | E2: PENDENTE
A3: descritiva 2 (autonomia/subsídio) | B3: contexto2 | C3: C.2 | D3: remapeado 1:1, sem reinterpretação | E3: PENDENTE
A4: itens Versão A | B4: 1.1–5.8; 3.b.1–3.b.6 | C4: idem + 2.11–2.12; 3.9–3.13; 3.b.4.1; 3.b.7 | D4: antigos preservados; novos acrescentados | E4: PENDENTE
A5: itens Versão B | B5: P1.1–P7.10 | C5: idem + P5.10–P5.11; P6.9–P6.13; P6.b.4.1; P6.b.6–P6.b.7; P7.11–P7.14 | D5: antigos preservados; novos acrescentados | E5: PENDENTE
A6: avaliações em andamento | B6: localStorage 'maria-assessment-state' | C6: chave versionada (…-v2) | D6: nenhuma avaliação v1 recalculada sob v2 | E6: PENDENTE
A7: relatórios exportados | B7: sem carimbo | C7: carimbo de versão da matriz | D7: export v1 preserva classificação original | E7: PENDENTE
